Workbook
Name solver_cvg: 0.0001
Name solver_drv: 1
Name solver_eng: 1
Name solver_est: 1
Name solver_itr: 2147483647
Name solver_mip: 2147483647
Name solver_mni: 30
Name solver_mrt: 0.075
Name solver_msl: 2
Name solver_neg: 1
Name solver_nod: 2147483647
Name solver_num: 14
Name solver_nwt: 1
Name solver_pre: 0.000001
Name solver_rbv: 1
Name solver_rel1: 2
Name solver_rel10: 3
Name solver_rel11: 1
Name solver_rel12: 3
Name solver_rel13: 1
Name solver_rel14: 3
Name solver_rel2: 3
Name solver_rel3: 3
Name solver_rel4: 3
Name solver_rel5: 1
Name solver_rel6: 3
Name solver_rel7: 1
Name solver_rel8: 3
Name solver_rel9: 1
Name solver_rhs10: 0
Name solver_rhs12: 0
Name solver_rhs14: 0
Name solver_rhs2: 0
Name solver_rhs3: 0
Name solver_rhs6: 0
Name solver_rhs8: 0
Name solver_rlx: 2
Name solver_rsd: 0
Name solver_scl: 1
Name solver_sho: 2
Name solver_ssz: 100
Name solver_tim: 120
Name solver_tol: 0.01
Name solver_typ: 1
Name solver_val: 0
Name solver_ver: 3
Name solver_lhs11: Optimizer!$B$25
Name solver_opt: Optimizer!$B$81
Name solver_lhs3: Optimizer!$AG$59:$AZ$59
Name solver_lhs12: Optimizer!$B$25
Name solver_rhs13: Optimizer!$B$8
Name solver_lhs5: Optimizer!$B$22
Name solver_lhs7: Optimizer!$B$23
Name solver_adj: Optimizer!$B$22:$B$26
Name solver_lhs4: Optimizer!$AG$78:$BA$78
Name solver_rhs1: Optimizer!$B$8
Name solver_lhs9: Optimizer!$B$24
Name solver_lhs13: Optimizer!$B$26
Name solver_rhs4: Optimizer!$B$8
Name solver_rhs11: Optimizer!$B$8

Sheet Description
A73: Observed shortcomings of Roth conversion resources
A74: Most existing resources/calculators are overly user-driven in that they provide some options like "lump sum", "fill desired tax bracket", "set dollar amount each year", etc. But this assumes people somehow already know which of these they want to do. IMO it should be the onus of the tool / advisor to be able to be flexible enough to consider all of these and recommend a strategy/course of action based on maximizing the objective of the user, one common one is just maximizing wealth. So, the user should be able to express their goal is to maximize wealth, provide all their other relevant inputs, and the tool should be able to simulate every possible scenario given these inputs and spit out the one that maximizes wealth. Albeit not exactly the same, this tool uses NPV as a proxy for wealth, since the ability to actually spend money (i.e. cash flows) is what gives it value.
A76: The boldin tool is the only one I've seen so far which captures this appropriately
A78: Tool Description
A80: a common financial strategy in early years of retirement is to spread roth conversions across a number of lower-than-previously years (since now retired) to minimize taxes from RMDs of traditional IRA later on. The idea is it's advantageous to pay a lower tax rate now to convert part of the traditional IRA balance into tax-free Roth than to be forced to pay a higher tax rate down the line due to RMDs and the projected growth of the traditional IRA balance. However, you may not have to wait until retirement to take advantage of this optimization. Anyone who finds themselves in a lower-than-normal income year could consider this.
A82: This tool is designed to help people who may find themselves with lower than usual income in a given year to take actions which may be advantageous for their finances. One of these actions is a traditional to roth conversion, which you'll find all sorts of mentions of online. However, what you probably won't find is an easy way to answer the question: "so, what's the optimal amount of money I should convert from my traditional retirement savings to roth?" This tool attempts to help you answer that question.
A84: The initial audience for this tool was graduate school students who had previously worked full-time prior to taking time off for full-time graduate school. But the tool could help people in a variety of situations, such as people working on a startup opting not to pay themselves for a while, people taking unpaid time off for parental leave, or any other break from full-time work that results in a year with lower than usual income and thus lower than usual taxes.
A86: The tool assumes a one-time conversion in year 0, followed by 30 years of work, followed by 20 years of retirement, followed by liquidation of any remaining retirement account balances in year 51.
A88: The analysis revolves around the notion of "filling up" progressive tax brackets by minimizing your marginal tax rate to maximize long term wealth. The tool essentially tries every possible roth conversion amount you could undertake and figures out which one maximizes total value over this 51 year time period, expressed in today's dollars (net present value). You can see the starting default values leave just enough unconverted in the traditional IRA such that only the lowest tax brackets (10 and 12%) are paid when the balance is ultimately drawn down. Plugging in different input values and studying the generated output helps build some intuition for what the tool is doing - you'll see the drivers and boundary conditions are usually around filling lower tax brackets and avoiding the next larger one.
A90: Note on inflation: You may notice that the annual retirement distribution amounts during the twenty year retirement period are in today's dollars and think "wait, shouldn't these be adjusted for inflation? I don't think $100K in today's dollars will be worth the same in 50 years." You're right, and the reason they're not is that the tool neither adjusts future tax brackets for inflation, and because of this the impact on NPV is offsetting. In reality, tax brackets are pegged to inflation rates, so both the tax bracket and the distribution amounts will increase by the same rates over time.
A92: mfj?
A94: Limitations
... A100: 3. The tool doesn't incorporate any value that may derive from the usage of traditional/roth IRAs in estate planning and wealth transfer. If these variables were to be included, it would likely tip the scales even further towards the Roth. While both vehicles are subject to the 10 year rule (both must be drawn down within 10 years of receipt), traditional withdrawals are taxable and mandate required minimum distributions (RMDs), while the Roth can be drawn down tax-free at any point within the 10 years, making it an efficient and flexible estate planning tool.

Sheet Optimizer
A1: Fixed Inputs
A2: Tax Year | B2: 2024
A3: Current Age | B3: 29
A4: Traditional (Pre-Tax) 401K/IRA Balance | B4: 300000
A5: Ordinary Income this tax year (i.e. Jan 1-Dec 31) | B5: 92200 | C5: 400000 | D5: 400000
A6: Investment return, working years | B6: 0.1
A7: Investment return, retirement | B7: 0.06
A8: annual withdrawal in retirement | B8: 250000 | C8: i.e. each year in retirement, withdraw this amount from combo of Traditional/Roth. This is in nominal future dollar terms
A9: Tax Liability without any Roth Conversion | B9: =B19 -> 15210 | C9: =C19 -> 103373 | D9: =D19 -> 103373
A10: Federal tax at 10% | B10: =IF(B$5>='Tax Brackets'!$B$4, 'Tax Brackets'!$B$4, B$5) -> 23200 | C10: =IF(C$5>='Tax Brackets'!$B$4, 'Tax Brackets'!$B$4, C$5) -> 23200 | D10: =IF(D$5>='Tax Brackets'!$B$4, 'Tax Brackets'!$B$4, D$5) -> 23200
A11: Federal tax at 12% | B11: =IF(B$5>='Tax Brackets'!$B5, 'Tax Brackets'!$B5-'Tax Brackets'!$B4, IF(B$5-'Tax Brackets'!$B4>=0, B$5-'Tax Brackets'!$B4, 0)) -> 69000 | C11: =IF(C$5>='Tax Brackets'!$B5, 'Tax Brackets'!$B5-'Tax Brackets'!$B4, IF(C$5-'Tax Brackets'!$B4>=0, C$5-'Tax Brackets'!$B4, 0)) -> 71100 | D11: =IF(D$5>='Tax Brackets'!$B5, 'Tax Brackets'!$B5-'Tax Brackets'!$B4, IF(D$5-'Tax Brackets'!$B4>=0, D$5-'Tax Brackets'!$B4, 0)) -> 71100
A12: Federal tax at 22% | B12: =IF(B$5>='Tax Brackets'!$B6, 'Tax Brackets'!$B6-'Tax Brackets'!$B5, IF(B$5-'Tax Brackets'!$B5>=0, B$5-'Tax Brackets'!$B5, 0)) -> 0 | C12: =IF(C$5>='Tax Brackets'!$B6, 'Tax Brackets'!$B6-'Tax Brackets'!$B5, IF(C$5-'Tax Brackets'!$B5>=0, C$5-'Tax Brackets'!$B5, 0)) -> 106750 | D12: =IF(D$5>='Tax Brackets'!$B6, 'Tax Brackets'!$B6-'Tax Brackets'!$B5, IF(D$5-'Tax Brackets'!$B5>=0, D$5-'Tax Brackets'!$B5, 0)) -> 106750
A13: Federal tax at 24% | B13: =IF(B$5>='Tax Brackets'!$B7, 'Tax Brackets'!$B7-'Tax Brackets'!$B6, IF(B$5-'Tax Brackets'!$B6>=0, B$5-'Tax Brackets'!$B6, 0)) -> 0 | C13: =IF(C$5>='Tax Brackets'!$B7, 'Tax Brackets'!$B7-'Tax Brackets'!$B6, IF(C$5-'Tax Brackets'!$B6>=0, C$5-'Tax Brackets'!$B6, 0)) -> 182850 | D13: =IF(D$5>='Tax Brackets'!$B7, 'Tax Brackets'!$B7-'Tax Brackets'!$B6, IF(D$5-'Tax Brackets'!$B6>=0, D$5-'Tax Brackets'!$B6, 0)) -> 182850
A14: Federal tax at 32% | B14: =IF(B$5>='Tax Brackets'!$B8, 'Tax Brackets'!$B8-'Tax Brackets'!$B7, IF(B$5-'Tax Brackets'!$B7>=0, B$5-'Tax Brackets'!$B7, 0)) -> 0 | C14: =IF(C$5>='Tax Brackets'!$B8, 'Tax Brackets'!$B8-'Tax Brackets'!$B7, IF(C$5-'Tax Brackets'!$B7>=0, C$5-'Tax Brackets'!$B7, 0)) -> 16100 | D14: =IF(D$5>='Tax Brackets'!$B8, 'Tax Brackets'!$B8-'Tax Brackets'!$B7, IF(D$5-'Tax Brackets'!$B7>=0, D$5-'Tax Brackets'!$B7, 0)) -> 16100
A15: Federal tax at 35% | B15: =IF(B$5>='Tax Brackets'!$B9, 'Tax Brackets'!$B9-'Tax Brackets'!$B8, IF(B$5-'Tax Brackets'!$B8>=0, B$5-'Tax Brackets'!$B8, 0)) -> 0 | C15: =IF(C$5>='Tax Brackets'!$B9, 'Tax Brackets'!$B9-'Tax Brackets'!$B8, IF(C$5-'Tax Brackets'!$B8>=0, C$5-'Tax Brackets'!$B8, 0)) -> 0 | D15: =IF(D$5>='Tax Brackets'!$B9, 'Tax Brackets'!$B9-'Tax Brackets'!$B8, IF(D$5-'Tax Brackets'!$B8>=0, D$5-'Tax Brackets'!$B8, 0)) -> 0
A16: Federal tax at 37% | B16: =IF(B$5>='Tax Brackets'!$B10, 'Tax Brackets'!$B10-'Tax Brackets'!$B9, IF(B$5-'Tax Brackets'!$B9>=0, B$5-'Tax Brackets'!$B9, 0)) -> 0 | C16: =IF(C$5>='Tax Brackets'!$B10, 'Tax Brackets'!$B10-'Tax Brackets'!$B9, IF(C$5-'Tax Brackets'!$B9>=0, C$5-'Tax Brackets'!$B9, 0)) -> 0 | D16: =IF(D$5>='Tax Brackets'!$B10, 'Tax Brackets'!$B10-'Tax Brackets'!$B9, IF(D$5-'Tax Brackets'!$B9>=0, D$5-'Tax Brackets'!$B9, 0)) -> 0
A17: State Tax at 5% | B17: =IF(B$5>='Tax Brackets'!$B$14, 'Tax Brackets'!$B$14, B$5) -> 92200 | C17: =IF(C$5>='Tax Brackets'!$B$14, 'Tax Brackets'!$B$14, C$5) -> 400000 | D17: =IF(D$5>='Tax Brackets'!$B$14, 'Tax Brackets'!$B$14, D$5) -> 400000
A18: State Tax at 9% | B18: =IF(B$5>='Tax Brackets'!$B15, 'Tax Brackets'!$B15-'Tax Brackets'!$B14, IF(B$5-'Tax Brackets'!$B14>=0, B$5-'Tax Brackets'!$B14, 0)) -> 0 | C18: =IF(C$5>='Tax Brackets'!$B15, 'Tax Brackets'!$B15-'Tax Brackets'!$B14, IF(C$5-'Tax Brackets'!$B14>=0, C$5-'Tax Brackets'!$B14, 0)) -> 0 | D18: =IF(D$5>='Tax Brackets'!$B15, 'Tax Brackets'!$B15-'Tax Brackets'!$B14, IF(D$5-'Tax Brackets'!$B14>=0, D$5-'Tax Brackets'!$B14, 0)) -> 0
A19: Overall Tax Payment | B19: =SUMPRODUCT('Tax Brackets'!$A$4:$A$10,B10:B16)+SUMPRODUCT('Tax Brackets'!$A$14:$A$15,B17:B18) -> 15210 | C19: =SUMPRODUCT('Tax Brackets'!$A$4:$A$10,C10:C16)+SUMPRODUCT('Tax Brackets'!$A$14:$A$15,C17:C18) -> 103373 | D19: =SUMPRODUCT('Tax Brackets'!$A$4:$A$10,D10:D16)+SUMPRODUCT('Tax Brackets'!$A$14:$A$15,D17:D18) -> 103373
A21: Variables
A22: Traditional->Roth Conversion Amount y0 | B22: 291239.65 | C22: i.e. how many dollars optimally converted from Traditional to Roth
A23: Traditional->Roth Conversion Amount y1 | B23: 6.714929e-08
A24: Traditional->Roth Conversion Amount y2 | B24: 0.00043996848
A25: Annual Withdrawal from Traditional | B25: 0
A26: Annual Withdrawal from Roth | B26: 250000
A28: Constraints | D28: Plain English Explanation
A29: =B22 -> 291239.65 | B29: <= | C29: =B4 -> 300000 | D29: Can't convert more than you have!
A30: =B22 -> 291239.65 | B30: >= | C30: 0 | D30: Can't convert a negative amount
A31: =B23 -> 6.714929e-08 | B31: <= | C31: =(B4-B22)*(1+B6) -> 9636.3864 | D31: second year conversion amount must be less than traditional balance in second year
A32: =B23 -> 6.714929e-08 | B32: >= | C32: 0 | D32: Can't convert a negative amount
A33: =B24 -> 0.00043996848 | B33: <= | C33: =(((B4-B22)*(1+B6))-B23)*(1+B6) -> 10600.025 | D33: third year conversion amount must be less than traditional balance in third year
A34: =B24 -> 0.00043996848 | B34: >= | C34: 0 | D34: Can't convert a negative amount
A35: =B25+B26 -> 250000 | B35: = | C35: =B8 -> 250000 | D35: Together, the withdrawal amounts from traditional and roth must equal the annual retirement withdrawal amount
A37: Scenario | AG37: Start 20 years of withdrawal
AG38: NOTE: withdrawal cash flow not adjusted for inflation because tax brackets are not either (in this model that is. in real life they do change with inflation), so the real tax impact should be the same as modelling as inflation adjusted withdrawal cash flow and inflation adjusted tax brackets | BA38: Liquidate | BB38: NOTE: Liquidation assumption is just to incorporate ending balances into NPV calculation
A39: Time | B39: 0 | C39: =B39+1 -> 1 | D39: =C39+1 -> 2 | E39: =D39+1 -> 3 | F39: =E39+1 -> 4 | G39: =F39+1 -> 5 | H39: =G39+1 -> 6 | I39: =H39+1 -> 7 | J39: =I39+1 -> 8 | ... BA39: =AZ39+1 -> 51
A40: Year | B40: 2024 | C40: =B40+1 -> 2025 | D40: =C40+1 -> 2026 | E40: =D40+1 -> 2027 | F40: =E40+1 -> 2028 | G40: =F40+1 -> 2029 | H40: =G40+1 -> 2030 | I40: =H40+1 -> 2031 | J40: =I40+1 -> 2032 | ... BA40: =AZ40+1 -> 2075
A41: Traditional 401K Balance | B41: =$B$4-$B$22 -> 8760.3513 | C41: =(1+$B$6)*B41-$B$23 -> 9636.3864 | D41: =(1+$B$6)*C41-$B$24 -> 10600.025 | E41: =(1+$B$6)*D41 -> 11660.027 | F41: =(1+$B$6)*E41 -> 12826.03 | G41: =(1+$B$6)*F41 -> 14108.633 | H41: =(1+$B$6)*G41 -> 15519.496 | I41: =(1+$B$6)*H41 -> 17071.446 | J41: =(1+$B$6)*I41 -> 18778.59 | K41: =(1+$B$6)*J41 -> 20656.449 | L41: =(1+$B$6)*K41 -> 22722.094 | ... AF41: =(1+$B$6)*AE41 -> 152862.89 | AG41: =(1+$B$7)*(AF41-AG43) -> 162034.66 | AH41: =(1+$B$7)*(AG41-AH43) -> 171756.74 | AI41: =(1+$B$7)*(AH41-AI43) -> 182062.14 | AJ41: =(1+$B$7)*(AI41-AJ43) -> 192985.87 | AK41: =(1+$B$7)*(AJ41-AK43) -> 204565.02 | AL41: =(1+$B$7)*(AK41-AL43) -> 216838.92 | AM41: =(1+$B$7)*(AL41-AM43) -> 229849.26 | AN41: =(1+$B$7)*(AM41-AN43) -> 243640.21 | ... AZ41: =(1+$B$7)*(AY41-AZ43) -> 362170.29 | BA41: =(1+$B$7)*AZ41 -> 383900.51
A42: Required Minimum Distribution (RMD) | AG42: =IF($B$3+AG39>='Uniform Lifetime Table'!$D$3, AF41/VLOOKUP($B$3+AG39,'Uniform Lifetime Table'!$A:$B,2,0), 0) -> 0 | AH42: =IF($B$3+AH39>='Uniform Lifetime Table'!$D$3, AG41/VLOOKUP($B$3+AH39,'Uniform Lifetime Table'!$A:$B,2,0), 0) -> 0 | AI42: =IF($B$3+AI39>='Uniform Lifetime Table'!$D$3, AH41/VLOOKUP($B$3+AI39,'Uniform Lifetime Table'!$A:$B,2,0), 0) -> 0 | AJ42: =IF($B$3+AJ39>='Uniform Lifetime Table'!$D$3, AI41/VLOOKUP($B$3+AJ39,'Uniform Lifetime Table'!$A:$B,2,0), 0) -> 0 | AK42: =IF($B$3+AK39>='Uniform Lifetime Table'!$D$3, AJ41/VLOOKUP($B$3+AK39,'Uniform Lifetime Table'!$A:$B,2,0), 0) -> 0 | AL42: =IF($B$3+AL39>='Uniform Lifetime Table'!$D$3, AK41/VLOOKUP($B$3+AL39,'Uniform Lifetime Table'!$A:$B,2,0), 0) -> 0 | AM42: =IF($B$3+AM39>='Uniform Lifetime Table'!$D$3, AL41/VLOOKUP($B$3+AM39,'Uniform Lifetime Table'!$A:$B,2,0), 0) -> 0 | AN42: =IF($B$3+AN39>='Uniform Lifetime Table'!$D$3, AM41/VLOOKUP($B$3+AN39,'Uniform Lifetime Table'!$A:$B,2,0), 0) -> 0 | ... BA42: =IF($B$3+BA39>='Uniform Lifetime Table'!$D$3, AZ41/VLOOKUP($B$3+BA39,'Uniform Lifetime Table'!$A:$B,2,0), 0) -> 17929.222
A43: Withdrawal Cash Flow | AG43: =MAX(MIN($B$8-$B$26, AF41),AG42) -> 0.00025265515 | AH43: =MAX(MIN($B$8-$B$26, AG41),AH42) -> 0.00025265515 | AI43: =MAX(MIN($B$8-$B$26, AH41),AI42) -> 0.00025265515 | AJ43: =MAX(MIN($B$8-$B$26, AI41),AJ42) -> 0.00025265515 | AK43: =MAX(MIN($B$8-$B$26, AJ41),AK42) -> 0.00025265515 | AL43: =MAX(MIN($B$8-$B$26, AK41),AL42) -> 0.00025265515 | AM43: =MAX(MIN($B$8-$B$26, AL41),AM42) -> 0.00025265515 | AN43: =MAX(MIN($B$8-$B$26, AM41),AN42) -> 0.00025265515 | ... AZ43: =MAX(MIN($B$8-$B$26, AY41),AZ42) -> 16998.512 | BA43: =BA41 -> 383900.51
...

Sheet Tax Brackets
A1: Tax Brackets
A2: 2024 Federal Income Tax Brackets
A3: Rate | B3: Income Range (MFJ) | C3: Income Range (MFS)
A4: 0.1 | B4: 23200 | C4: 11600
A5: 0.12 | B5: 94300 | C5: 47150
A6: 0.22 | B6: 201050 | C6: 100525
A7: 0.24 | B7: 383900 | C7: 191950
A8: 0.32 | B8: 487450 | C8: 243725
A9: 0.35 | B9: 731200 | C9: 365600
A10: 0.37 | B10: =10^12 -> 1000000000000 | C10: =10^12 -> 1000000000000 | D10: NOTE: just using a very large number to represent top bracket
A12: 2024 MA State Income Tax Brackets | D12: NOTE: Just type in 0 if your state doesn't have state income tax
A13: Rate | B13: Income Range (MFJ) | C13: Income Range (MFS)
A14: 0.05 | B14: 1000000 | C14: 1000000
A15: 0.09 | B15: =10^12 -> 1000000000000 | C15: =10^12 -> 1000000000000 | D15: NOTE: I believe this is the "MA Millionairres Tax" of an additional 4% that went into effect in 2023
A17: 2024 Federal LTCG Tax Brackets
A18: Rate | B18: Income Range (MFJ) | C18: Income Range (MFS)
A19: 0 | B19: 94050 | C19: 47025
A20: 0.15 | B20: 583750 | C20: 291850
A21: 0.2 | B21: =10^12 -> 1000000000000 | C21: =10^12 -> 1000000000000
A23: 2024 MA State LTCG Tax Brackets
A24: Rate | B24: Gain Range (MFJ) | C24: Gain Range (MFS)
A25: 0.05 | B25: =10^12 -> 1000000000000 | C25: =10^12 -> 1000000000000 | D25: NOTE: flat 5% on LTCG

Sheet Uniform Lifetime Table
A1: https://www.irs.gov/publications/p590b#en_US_2023_publink100090310
A3: Age at which RMDs kick-in | D3: 73
A5: Age | B5: Distribution Period
A6: 72 | B6: 27.4
A7: 73 | B7: 26.5
A8: 74 | B8: 25.5
A9: 75 | B9: 24.6
A10: 76 | B10: 23.7
A11: 77 | B11: 22.9
A12: 78 | B12: 22
A13: 79 | B13: 21.1
A14: 80 | B14: 20.2
A15: 81 | B15: 19.4
A16: 82 | B16: 18.5
A17: 83 | B17: 17.7
... A53: 119 | B53: 2.3
A54: 120 and over | B54: 2

Sheet Resources
A1: How capital gains income interacts ("stacks on top of") with ordinary income | B1: https://www.kitces.com/blog/long-term-capital-gains-bump-zone-higher-marginal-tax-rate-phase-in-0-rate/
A16: Other learnings:
A17: - Roth distributions in retirement do not "push up" other taxable income into higher tax brackets. So you can take any amount of qualified Roth distributions and also fill the first 0% LTCG bracket with investment sales without paying any tax
